Workbook

Sheet Assumptions
A1: Assumptions — paper-authoritative constants (v1.0.0). Typed values are inputs; every other number is a formula. Sources in column D.
A3: Anchor Wh per 100-input / 300-output-token query (GPT-4o-mini) | B3: 0.577 | D3: Jegham et al. [15]; 100 input + 300 output tokens (Section 4.4)
A4: Per-1,000-token conversion factor | B4: =1000/300 -> 3.3333333 | D4: Equals 1000/300 total tokens (Appendix D.5.1 -- 100 input tokens, 300 output tokens, not 400 tokens)
A5: Anchor TPS (gpt-4o-mini, campaign P50) | B5: 78.3 | D5: Frozen corpus 24 Jun-22 Aug 2026 (SHA-256 01c57eb5...84cc6), n=105
A6: PUE multiplier (central, absolute) | B6: 1.05 | D6: PUE_Calculation_Aug2026.xlsx / Table D1
A7: PQPC for GPT-5.x | B7: 2.99 | D7: Section 4.10 (GB200/GB300-dominant fleet)
A8: PQPC for GPT-4o-mini | B8: 1 | D8: Appendix D.5.4 (A100-era anchor deployment)
A9: Location-based intensity gCO2e/Wh | B9: 0.353 | D9: Table 3 / Section 4.7
A10: Market-based intensity gCO2e/Wh (Stargate credited at Oracle FY25 corporate 46 gCO2e/kWh; Google credited at CY2025 realised market-based Scope 2 — Section 4.8) | B10: =ROUND(GridIntensity!F20,1)/1000 -> 0.0516 | D10: Table 5 / Section 4.8 — computed in GridIntensity!F20
A11: A_low | B11: 0.43 | D11: Appendix D.6: Epoch 0.30 Wh @500 out = 0.60 Wh/1,000 output tokens; Jegham GPT-4o 0.423 Wh @300 out = 1.41; A_low = 0.60/1.41.
A12: A_high | B12: 1.2 | D12: Appendix D.6: upward allowance for Jegham boundary omissions (provisioned-idle and overhead), ~18% of full-stack energy in Google's decomposition [2].
A13: PQPC_low (relative) | B13: 0.53 | D13: Section 4.10
A14: PQPC_high (relative) | B14: 1.48 | D14: Section 4.10
A15: P_low | B15: 0.95 | D15: Table D1 relative
A16: P_high | B16: 1.03 | D16: Table D1 relative
A17: Fixed_low GPT-5.x | B17: =B11*B13*B15 -> 0.216505 | D17: Formula: A_low x PQPC_low x P_low
A18: Fixed_high GPT-5.x | B18: =B12*B14*B16 -> 1.82928 | D18: Formula: A_high x PQPC_high x P_high
A19: Fixed_low GPT-4o-mini | B19: =B11*1*B15 -> 0.4085 | D19: Formula: A_low x 1 x P_low
A20: Fixed_high GPT-4o-mini | B20: =B12*1*B16 -> 1.236 | D20: Formula: A_high x 1 x P_high
A21: Market-based intensity gCO2e/Wh, procurement-lag scenario (Stargate uncredited — Section 4.8 / Table 10: 159 gCO2e/kWh) | B21: =ROUND(GridIntensity!G30,1)/1000 -> 0.1589 | D21: Table 10 procurement-lag row — computed in GridIntensity!G30
A22: Corpus provenance: InferenceCarbon_corpus_frozen_20260822.zip, SHA-256 01c57eb5bf41476fee8e06a8b677a72c172c849741cc65a9b554cf7397d84cc6. Copyright (c) 2026 InferenceCarbon Ltd.

Sheet GridIntensity
A1: GridIntensity — Tables 3, 4, 5 and 10 (Sections 4.5 – 4.8, 5.4). Typed values are inputs; every other number is a formula. Google is credited at its GHG Protocol 2015 market-based Scope 2 realised intensity (Google 2026 Environmental Report, CY2025).
A3: Google inputs (2026 Environmental Report, Environmental metrics data tables, pp. 89, 92)
A4: Scope 2 market-based, CY2025 (tCO2e) | B4: 2815000 | D4: Google 2026 Environmental Report, p. 89 — third-party limited assurance
A5: Scope 2 location-based, CY2025 (tCO2e) | B5: 15148700 | D5: Google 2026 Environmental Report, p. 89
A6: Total electricity consumption, CY2025 (MWh) | B6: 43586600 | D6: Google 2026 Environmental Report, p. 92 (data centres 42,415,800 MWh = 97.3%)
A7: Scope 2 market-based, CY2024 (tCO2e) | B7: 2898600 | D7: Google 2026 Environmental Report, p. 89
A8: Total electricity consumption, CY2024 (MWh) | B8: 31713900 | D8: Google 2026 Environmental Report, p. 92
A9: Hourly CFE, data centres, CY2025 (%) | B9: 65 | D9: Google 2026 Environmental Report, p. 93 — reported alongside, not instead of, market-based Scope 2; not used in Table 4
A10: Google realised market-based intensity, CY2025 (gCO2e/kWh) | B10: =B4/B6*1000 -> 64.584069 | D10: tCO2e × 1e6 / (MWh × 1e3) — Section 3.7 realised-intensity rule, as applied to Microsoft [32] and Oracle [16]
A11: Google realised location-based intensity, CY2025 (gCO2e/kWh) | B11: =B5/B6*1000 -> 347.55406 | D11: Cross-check on Appendix D.3 assessed GCP intensity of 335 (row 17)
A12: Google realised market-based intensity, CY2024 (gCO2e/kWh) | B12: =B7/B8*1000 -> 91.398409 | D12: Prior-year comparator only
A14: Tables 3 – 5: provider routing shares and intensities
A15: Provider | B15: Routing share (Section 4.5) | C15: Location-based gCO2e/kWh (Section 4.6) | D15: LB contribution (Table 3) | E15: Market-based gCO2e/kWh (Table 4) | F15: MB contribution (Table 5) | G15: Market-based basis
A16: Microsoft Azure | B16: 0.234 | C16: 447 | D16: =B16*C16 -> 104.598 | E16: 73 | F16: =B16*E16 -> 17.082 | G16: FY2025 reported market-based Scope 2: 2,707,428 mtCO2e / 37.0 TWh [32]
A17: Oracle / Stargate | B17: 0.393 | C17: 319 | D17: =B17*C17 -> 125.367 | E17: 46 | F17: =B17*E17 -> 18.078 | G17: FY25 reported market-based Scope 2: 237,251 tCO2e / 5.16 TWh [16]; out-of-period
A18: Amazon Web Services | B18: 0.117 | C18: 319 | D18: =B18*C18 -> 37.323 | E18: 0 | F18: =B18*E18 -> 0 | G18: 100% annual match claimed, credited at face value; no AWS-level intensity computable (limitation 27)
A19: Google Cloud Platform | B19: 0.255 | C19: 335 | D19: =B19*C19 -> 85.425 | E19: =B10 -> 64.584069 | F19: =B19*E19 -> 16.468938 | G19: CY2025 reported market-based Scope 2: 2,815,000 tCO2e / 43,586,600 MWh (row 10)
A20: Weighted total | B20: =SUM(B16:B19) -> 0.999 | D20: =SUM(D16:D19) -> 352.713 | F20: =SUM(F16:F19) -> 51.628938 | G20: D20 = Table 3 location-based total; F20 = Table 5 market-based total
A21: Market-based reduction vs location-based (%) | B21: =1-F20/D20 -> 0.85362338
A22: Google share of market-based total (%) | B22: =F19/F20 -> 0.31898657
A23: Oracle/Stargate share of market-based total (%) | B23: =F17/F20 -> 0.35015247
A24: Google market-based conversion multiplier (Table 4) | B24: =E19/C19 -> 0.19278827
A26: Table 10: routing-share sensitivity (Section 5.4)
A27: Routing scenario | B27: Azure | C27: Oracle / Stargate | D27: AWS | E27: GCP | F27: Location-based gCO2e/kWh | G27: Market-based gCO2e/kWh
A28: Azure-dominant illustration (70 / 10 / 5 / 15) | B28: 0.7 | C28: 0.1 | D28: 0.05 | E28: 0.15 | F28: =B28*$C$16+C28*$C$17+D28*$C$18+E28*$C$19 -> 411 | G28: =B28*$E$16+C28*$E$17+D28*$E$18+E28*$E$19 -> 65.38761
A29: Contract-weighted central (23.4 / 39.3 / 11.7 / 25.5) | B29: =B16 -> 0.234 | C29: =B17 -> 0.393 | D29: =B18 -> 0.117 | E29: =B19 -> 0.255 | F29: =B29*$C$16+C29*$C$17+D29*$C$18+E29*$C$19 -> 352.713 | G29: =B29*$E$16+C29*$E$17+D29*$E$18+E29*$E$19 -> 51.628938
A30: Procurement-lag scenario: Stargate uncredited (23.4 / 39.3 / 11.7 / 25.5) | B30: =B16 -> 0.234 | C30: =B17 -> 0.393 | D30: =B18 -> 0.117 | E30: =B19 -> 0.255 | F30: =B30*$C$16+C30*$C$17+D30*$C$18+E30*$C$19 -> 352.713 | G30: =B30*$E$16+C30*$C$17+D30*$E$18+E30*$E$19 -> 158.91794
A31: Stargate-ramped illustration (15 / 70 / 5 / 10) | B31: 0.15 | C31: 0.7 | D31: 0.05 | E31: 0.1 | F31: =B31*$C$16+C31*$C$17+D31*$C$18+E31*$C$19 -> 339.8 | G31: =B31*$E$16+C31*$E$17+D31*$E$18+E31*$E$19 -> 49.608407
A33: Procurement-lag row credits Oracle/Stargate at its location-based intensity (319) rather than its reported FY25 market-based Scope 2 (46).

Sheet Corpus
A1: Measured inputs from the frozen corpus (24 Jun - 22 Aug 2026). All values are measured data (medians / daily-median stats), not editable assumptions.
A2: Row label | B2: Corpus label | C2: TPS median (P50) | D2: n TPS | E2: TPS daily-median mean | F2: TPS daily-median SD | G2: days | H2: R central (1k hard) | I2: n | J2: R short (100/300 hard) | K2: n | L2: R long (10k hard) | M2: n | N2: R floor (easy 10k) | O2: R heavy (k=36) | P2: n | Q2: Mode | R2: PQPC class
A3: gpt-4o-mini | B3: gpt-4o-mini | C3: 78.3 | D3: 105 | E3: 80.1 | F3: 23.9 | G3: 57 | H3: 1 | I3: 47 | J3: 1 | K3: 46 | L3: 1 | M3: 4 | N3: 1 | O3: 1 | P3: 12 | Q3: None | R3: 4o
A4: gpt-5 (non-reasoning) | B4: gpt-5 (minimal) | C4: 60.78 | D4: 102 | E4: 61.4 | F4: 13.3 | G4: 57 | H4: 1 | I4: 46 | J4: 1 | K4: 45 | L4: 1 | M4: 4 | N4: 1 | O4: 1 | P4: 14 | Q4: None | R4: 5x
A5: gpt-5 (low) | B5: gpt-5 (low) | C5: 61 | D5: 102 | E5: 61.7 | F5: 14.2 | G5: 57 | H5: 2.23 | I5: 43 | J5: 3.31 | K5: 45 | L5: 1.87 | M5: 3 | N5: 1.15 | O5: 5.11 | P5: 13 | Q5: Low | R5: 5x
A6: gpt-5 (medium) | B6: gpt-5 (medium) | C6: 63.47 | D6: 103 | E6: 60.8 | F6: 14.5 | G6: 57 | H6: 3.84 | I6: 37 | J6: 5.81 | K6: 36 | L6: 3.34 | M6: 2 | N6: 1.63 | O6: 8.23 | P6: 12 | Q6: Medium | R6: 5x
A7: gpt-5 (high) | B7: gpt-5 (high) | C7: 69 | D7: 94 | E7: 68.1 | F7: 15.7 | G7: 56 | H7: 6.12 | I7: 32 | J7: 9.1 | K7: 34 | M7: 0 | N7: 3.24 | O7: 14.39 | P7: 12 | Q7: High | R7: 5x
A8: gpt-5 (xhigh) | B8: gpt-5 (xhigh) | C8: 61.85 | D8: 101 | E8: 63.8 | F8: 16.7 | G8: 56 | H8: 3.75 | I8: 38 | J8: 5.77 | K8: 35 | L8: 3.59 | M8: 2 | N8: 1.67 | O8: 8.71 | P8: 12 | Q8: xHigh | R8: 5x
A9: gpt-5.2 (non-reasoning) | B9: gpt-5.2 (minimal) | C9: 60.3 | D9: 102 | E9: 59.6 | F9: 6.4 | G9: 57 | H9: 1 | I9: 40 | J9: 1 | K9: 37 | L9: 1 | M9: 4 | N9: 1 | O9: 1 | P9: 20 | Q9: None | R9: 5x
A10: gpt-5.2 (low) | B10: gpt-5.2 (low) | C10: 57.53 | D10: 102 | E10: 57 | F10: 6 | G10: 57 | H10: 1.67 | I10: 39 | J10: 1.89 | K10: 37 | L10: 1.5 | M10: 4 | N10: 1.02 | O10: 2.71 | P10: 13 | Q10: Low | R10: 5x
A11: gpt-5.2 (medium) | B11: gpt-5.2 (medium) | C11: 57.78 | D11: 101 | E11: 57.9 | F11: 6.3 | G11: 57 | H11: 1.84 | I11: 39 | J11: 2.27 | K11: 37 | L11: 1.69 | M11: 4 | N11: 1.07 | O11: 3.58 | P11: 12 | Q11: Medium | R11: 5x
A12: gpt-5.2 (high) | B12: gpt-5.2 (high) | C12: 57.09 | D12: 100 | E12: 57.5 | F12: 6.4 | G12: 56 | H12: 2.03 | I12: 39 | J12: 2.39 | K12: 37 | L12: 1.87 | M12: 4 | N12: 1.09 | O12: 4.06 | P12: 12 | Q12: High | R12: 5x
A13: gpt-5.2 (xhigh) | B13: gpt-5.2 (xhigh) | C13: 59.39 | D13: 102 | E13: 59.1 | F13: 6.9 | G13: 56 | H13: 3.22 | I13: 34 | J13: 3.59 | K13: 37 | M13: 0 | N13: 1.48 | O13: 7.08 | P13: 12 | Q13: xHigh | R13: 5x
A14: gpt-5.4-nano (non-reasoning) | B14: gpt-5.4-nano (minimal) | C14: 156.58 | D14: 102 | E14: 156.6 | F14: 18.7 | G14: 57 | H14: 1 | I14: 40 | J14: 1 | K14: 37 | L14: 1 | M14: 4 | N14: 1 | O14: 1 | P14: 20 | Q14: None | R14: 5x
A15: gpt-5.4-nano (low) | B15: gpt-5.4-nano (low) | C15: 153.07 | D15: 102 | E15: 154.1 | F15: 18.5 | G15: 57 | H15: 1.61 | I15: 40 | J15: 1.73 | K15: 37 | L15: 1.46 | M15: 4 | N15: 1.02 | O15: 2.85 | P15: 20 | Q15: Low | R15: 5x
A16: gpt-5.4-nano (medium) | B16: gpt-5.4-nano (medium) | C16: 156 | D16: 102 | E16: 152.3 | F16: 22.1 | G16: 57 | H16: 1.83 | I16: 40 | J16: 1.98 | K16: 37 | L16: 1.83 | M16: 4 | N16: 1.07 | O16: 3.62 | P16: 20 | Q16: Medium | R16: 5x
A17: gpt-5.4-nano (high) | B17: gpt-5.4-nano (high) | C17: 157.47 | D17: 100 | E17: 155.2 | F17: 19.5 | G17: 56 | H17: 1.97 | I17: 39 | J17: 2.1 | K17: 37 | L17: 2.01 | M17: 4 | N17: 1.1 | O17: 4.41 | P17: 14 | Q17: High | R17: 5x
A18: gpt-5.4-nano (xhigh) | B18: gpt-5.4-nano (xhigh) | C18: 154.37 | D18: 99 | E18: 153.7 | F18: 19.8 | G18: 56 | H18: 3.7 | I18: 39 | J18: 4.1 | K18: 37 | L18: 3.89 | M18: 4 | N18: 2.03 | O18: 8.31 | P18: 12 | Q18: xHigh | R18: 5x
A19: gpt-5.4-mini (non-reasoning) | B19: gpt-5.4-mini (minimal) | C19: 145.41 | D19: 103 | E19: 140.5 | F19: 18.1 | G19: 57 | H19: 1 | I19: 40 | J19: 1 | K19: 37 | L19: 1 | M19: 4 | N19: 1 | O19: 1 | P19: 20 | Q19: None | R19: 5x
A20: gpt-5.4-mini (low) | B20: gpt-5.4-mini (low) | C20: 138.64 | D20: 102 | E20: 137.2 | F20: 14.3 | G20: 57 | H20: 1.44 | I20: 40 | J20: 1.51 | K20: 37 | L20: 1.31 | M20: 4 | N20: 1.01 | O20: 2.19 | P20: 20 | Q20: Low | R20: 5x
A21: gpt-5.4-mini (medium) | B21: gpt-5.4-mini (medium) | C21: 140.63 | D21: 102 | E21: 136.7 | F21: 15.2 | G21: 57 | H21: 1.67 | I21: 40 | J21: 1.78 | K21: 37 | L21: 1.72 | M21: 4 | N21: 1.08 | O21: 3.66 | P21: 20 | Q21: Medium | R21: 5x
A22: gpt-5.4-mini (high) | B22: gpt-5.4-mini (high) | C22: 142.46 | D22: 100 | E22: 140.4 | F22: 13.5 | G22: 56 | H22: 2.91 | I22: 39 | J22: 2.65 | K22: 37 | L22: 2.56 | M22: 4 | N22: 1.25 | O22: 6.81 | P22: 12 | Q22: High | R22: 5x
A23: gpt-5.4-mini (xhigh) | B23: gpt-5.4-mini (xhigh) | C23: 145.78 | D23: 33 | E23: 139.2 | F23: 24.5 | G23: 23 | H23: 12.49 | I23: 26 | J23: 12.5 | K23: 33 | L23: 5.23 | M23: 1 | N23: 3.71 | O23: 35.9 | P23: 12 | Q23: xHigh | R23: 5x
A24: gpt-5.4 (non-reasoning) | B24: gpt-5.4 (minimal) | C24: 85.94 | D24: 102 | E24: 86 | F24: 12.7 | G24: 57 | H24: 1 | I24: 40 | J24: 1 | K24: 37 | L24: 1 | M24: 4 | N24: 1 | O24: 1 | P24: 20 | Q24: None | R24: 5x
A25: gpt-5.4 (low) | B25: gpt-5.4 (low) | C25: 91.65 | D25: 102 | E25: 92.1 | F25: 16.3 | G25: 57 | H25: 1.35 | I25: 40 | J25: 1.41 | K25: 36 | L25: 1.28 | M25: 4 | N25: 1.01 | O25: 1.99 | P25: 14 | Q25: Low | R25: 5x
... A49: gpt-5.6-terra (xhigh) | B49: gpt-5.6-terra (xhigh) | C49: 95.22 | D49: 66 | E49: 94.7 | F49: 8.4 | G49: 40 | H49: 1.68 | I49: 39 | J49: 1.94 | K49: 36 | L49: 1.57 | M49: 3 | N49: 1.08 | O49: 3.88 | P49: 20 | Q49: xHigh | R49: 5x

Sheet Table6
A1: Table 6 — Anchor scaling chain (all formulas). Anchor 0.577 Wh x 3.333 -> TPS scale -> PUE -> PQPC -> Reasoning multiplier.
A2: Model | B2: Anchor Wh/1,000 tokens | C2: Tokens-Per-Second | D2: TPS Adjustment | E2: TPS-Scaled Wh | F2: PUE Multiplier | G2: PUE-Adjusted Wh | H2: PQPC | I2: PQPC-Adjusted Wh | J2: Reasoning Mode | K2: Reasoning Multiplier | L2: Adjusted Per-Model Wh/1,000 tokens
A3: gpt-4o-mini | B3: =Assumptions!$B$3*Assumptions!$B$4 -> 1.9233333 | C3: =Corpus!C3 -> 78.3 | D3: =Assumptions!$B$5/C3 -> 1 | E3: =B3*D3 -> 1.9233333 | F3: =Assumptions!$B$6 -> 1.05 | G3: =E3*F3 -> 2.0195 | H3: =IF(Corpus!R3="5x",Assumptions!$B$7,Assumptions!$B$8) -> 1 | I3: =G3*H3 -> 2.0195 | J3: =Corpus!Q3 -> None | K3: =Corpus!H3 -> 1 | L3: =I3*K3 -> 2.0195
A4: gpt-5 (non-reasoning) | B4: =Assumptions!$B$3*Assumptions!$B$4 -> 1.9233333 | C4: =Corpus!C4 -> 60.78 | D4: =Assumptions!$B$5/C4 -> 1.2882527 | E4: =B4*D4 -> 2.4777394 | F4: =Assumptions!$B$6 -> 1.05 | G4: =E4*F4 -> 2.6016264 | H4: =IF(Corpus!R4="5x",Assumptions!$B$7,Assumptions!$B$8) -> 2.99 | I4: =G4*H4 -> 7.7788628 | J4: =Corpus!Q4 -> None | K4: =Corpus!H4 -> 1 | L4: =I4*K4 -> 7.7788628
A5: gpt-5 (low) | B5: =Assumptions!$B$3*Assumptions!$B$4 -> 1.9233333 | C5: =Corpus!C5 -> 61 | D5: =Assumptions!$B$5/C5 -> 1.2836066 | E5: =B5*D5 -> 2.4688033 | F5: =Assumptions!$B$6 -> 1.05 | G5: =E5*F5 -> 2.5922434 | H5: =IF(Corpus!R5="5x",Assumptions!$B$7,Assumptions!$B$8) -> 2.99 | I5: =G5*H5 -> 7.7508079 | J5: =Corpus!Q5 -> Low | K5: =Corpus!H5 -> 2.23 | L5: =I5*K5 -> 17.284302
A6: gpt-5 (medium) | B6: =Assumptions!$B$3*Assumptions!$B$4 -> 1.9233333 | C6: =Corpus!C6 -> 63.47 | D6: =Assumptions!$B$5/C6 -> 1.2336537 | E6: =B6*D6 -> 2.3727273 | F6: =Assumptions!$B$6 -> 1.05 | G6: =E6*F6 -> 2.4913636 | H6: =IF(Corpus!R6="5x",Assumptions!$B$7,Assumptions!$B$8) -> 2.99 | I6: =G6*H6 -> 7.4491773 | J6: =Corpus!Q6 -> Medium | K6: =Corpus!H6 -> 3.84 | L6: =I6*K6 -> 28.604841
A7: gpt-5 (high) | B7: =Assumptions!$B$3*Assumptions!$B$4 -> 1.9233333 | C7: =Corpus!C7 -> 69 | D7: =Assumptions!$B$5/C7 -> 1.1347826 | E7: =B7*D7 -> 2.1825652 | F7: =Assumptions!$B$6 -> 1.05 | G7: =E7*F7 -> 2.2916935 | H7: =IF(Corpus!R7="5x",Assumptions!$B$7,Assumptions!$B$8) -> 2.99 | I7: =G7*H7 -> 6.8521635 | J7: =Corpus!Q7 -> High | K7: =Corpus!H7 -> 6.12 | L7: =I7*K7 -> 41.935241
A8: gpt-5 (xhigh) | B8: =Assumptions!$B$3*Assumptions!$B$4 -> 1.9233333 | C8: =Corpus!C8 -> 61.85 | D8: =Assumptions!$B$5/C8 -> 1.265966 | E8: =B8*D8 -> 2.4348747 | F8: =Assumptions!$B$6 -> 1.05 | G8: =E8*F8 -> 2.5566184 | H8: =IF(Corpus!R8="5x",Assumptions!$B$7,Assumptions!$B$8) -> 2.99 | I8: =G8*H8 -> 7.6442891 | J8: =Corpus!Q8 -> xHigh | K8: =Corpus!H8 -> 3.75 | L8: =I8*K8 -> 28.666084
A9: gpt-5.2 (non-reasoning) | B9: =Assumptions!$B$3*Assumptions!$B$4 -> 1.9233333 | C9: =Corpus!C9 -> 60.3 | D9: =Assumptions!$B$5/C9 -> 1.2985075 | E9: =B9*D9 -> 2.4974627 | F9: =Assumptions!$B$6 -> 1.05 | G9: =E9*F9 -> 2.6223358 | H9: =IF(Corpus!R9="5x",Assumptions!$B$7,Assumptions!$B$8) -> 2.99 | I9: =G9*H9 -> 7.8407841 | J9: =Corpus!Q9 -> None | K9: =Corpus!H9 -> 1 | L9: =I9*K9 -> 7.8407841
A10: gpt-5.2 (low) | B10: =Assumptions!$B$3*Assumptions!$B$4 -> 1.9233333 | C10: =Corpus!C10 -> 57.53 | D10: =Assumptions!$B$5/C10 -> 1.361029 | E10: =B10*D10 -> 2.6177125 | F10: =Assumptions!$B$6 -> 1.05 | G10: =E10*F10 -> 2.7485981 | H10: =IF(Corpus!R10="5x",Assumptions!$B$7,Assumptions!$B$8) -> 2.99 | I10: =G10*H10 -> 8.2183084 | J10: =Corpus!Q10 -> Low | K10: =Corpus!H10 -> 1.67 | L10: =I10*K10 -> 13.724575
A11: gpt-5.2 (medium) | B11: =Assumptions!$B$3*Assumptions!$B$4 -> 1.9233333 | C11: =Corpus!C11 -> 57.78 | D11: =Assumptions!$B$5/C11 -> 1.3551402 | E11: =B11*D11 -> 2.6063863 | F11: =Assumptions!$B$6 -> 1.05 | G11: =E11*F11 -> 2.7367056 | H11: =IF(Corpus!R11="5x",Assumptions!$B$7,Assumptions!$B$8) -> 2.99 | I11: =G11*H11 -> 8.1827498 | J11: =Corpus!Q11 -> Medium | K11: =Corpus!H11 -> 1.84 | L11: =I11*K11 -> 15.05626
A12: gpt-5.2 (high) | B12: =Assumptions!$B$3*Assumptions!$B$4 -> 1.9233333 | C12: =Corpus!C12 -> 57.09 | D12: =Assumptions!$B$5/C12 -> 1.3715187 | E12: =B12*D12 -> 2.6378875 | F12: =Assumptions!$B$6 -> 1.05 | G12: =E12*F12 -> 2.7697819 | H12: =IF(Corpus!R12="5x",Assumptions!$B$7,Assumptions!$B$8) -> 2.99 | I12: =G12*H12 -> 8.281648 | J12: =Corpus!Q12 -> High | K12: =Corpus!H12 -> 2.03 | L12: =I12*K12 -> 16.811745
A13: gpt-5.2 (xhigh) | B13: =Assumptions!$B$3*Assumptions!$B$4 -> 1.9233333 | C13: =Corpus!C13 -> 59.39 | D13: =Assumptions!$B$5/C13 -> 1.3184038 | E13: =B13*D13 -> 2.5357299 | F13: =Assumptions!$B$6 -> 1.05 | G13: =E13*F13 -> 2.6625164 | H13: =IF(Corpus!R13="5x",Assumptions!$B$7,Assumptions!$B$8) -> 2.99 | I13: =G13*H13 -> 7.9609241 | J13: =Corpus!Q13 -> xHigh | K13: =Corpus!H13 -> 3.22 | L13: =I13*K13 -> 25.634176
A14: gpt-5.4-nano (non-reasoning) | B14: =Assumptions!$B$3*Assumptions!$B$4 -> 1.9233333 | C14: =Corpus!C14 -> 156.58 | D14: =Assumptions!$B$5/C14 -> 0.50006387 | E14: =B14*D14 -> 0.9617895 | F14: =Assumptions!$B$6 -> 1.05 | G14: =E14*F14 -> 1.009879 | H14: =IF(Corpus!R14="5x",Assumptions!$B$7,Assumptions!$B$8) -> 2.99 | I14: =G14*H14 -> 3.0195381 | J14: =Corpus!Q14 -> None | K14: =Corpus!H14 -> 1 | L14: =I14*K14 -> 3.0195381
... A49: gpt-5.6-terra (xhigh) | B49: =Assumptions!$B$3*Assumptions!$B$4 -> 1.9233333 | C49: =Corpus!C49 -> 95.22 | D49: =Assumptions!$B$5/C49 -> 0.82230624 | E49: =B49*D49 -> 1.581569 | F49: =Assumptions!$B$6 -> 1.05 | G49: =E49*F49 -> 1.6606474 | H49: =IF(Corpus!R49="5x",Assumptions!$B$7,Assumptions!$B$8) -> 2.99 | I49: =G49*H49 -> 4.9653359 | J49: =Corpus!Q49 -> xHigh | K49: =Corpus!H49 -> 1.68 | L49: =I49*K49 -> 8.3417643
A51: gpt-5.6-sol (max)*: xhigh values carried as explicit floors (limitation 18; tier not measured before the close). All 46 measured variants are carried; the gpt-5 effort ladder is non-monotonic (R 6.12 at high, 3.75 at xhigh).

Sheet Table7
A1: Table 7 — Conversion to location-based and market-based gCO2e/1,000 tokens.
A2: Model | B2: Adjusted Per-Model Wh/1,000 tokens | C2: LB gCO2e/Wh | D2: MB gCO2e/Wh | E2: Location-Based gCO2e/1,000 tokens | F2: Market-Based gCO2e/1,000 tokens | G2: Market-Based (procurement-lag) gCO2e/1,000 tokens
A3: gpt-4o-mini | B3: =Table6!L3 -> 2.0195 | C3: =Assumptions!$B$9 -> 0.353 | D3: =Assumptions!$B$10 -> 0.0516 | E3: =B3*C3 -> 0.7128835 | F3: =B3*D3 -> 0.1042062 | G3: =B3*Assumptions!$B$21 -> 0.32089855
A4: gpt-5 (non-reasoning) | B4: =Table6!L4 -> 7.7788628 | C4: =Assumptions!$B$9 -> 0.353 | D4: =Assumptions!$B$10 -> 0.0516 | E4: =B4*C4 -> 2.7459386 | F4: =B4*D4 -> 0.40138932 | G4: =B4*Assumptions!$B$21 -> 1.2360613
A5: gpt-5 (low) | B5: =Table6!L5 -> 17.284302 | C5: =Assumptions!$B$9 -> 0.353 | D5: =Assumptions!$B$10 -> 0.0516 | E5: =B5*C5 -> 6.1013585 | F5: =B5*D5 -> 0.89186996 | G5: =B5*Assumptions!$B$21 -> 2.7464755
A6: gpt-5 (medium) | B6: =Table6!L6 -> 28.604841 | C6: =Assumptions!$B$9 -> 0.353 | D6: =Assumptions!$B$10 -> 0.0516 | E6: =B6*C6 -> 10.097509 | F6: =B6*D6 -> 1.4760098 | G6: =B6*Assumptions!$B$21 -> 4.5453092
A7: gpt-5 (high) | B7: =Table6!L7 -> 41.935241 | C7: =Assumptions!$B$9 -> 0.353 | D7: =Assumptions!$B$10 -> 0.0516 | E7: =B7*C7 -> 14.80314 | F7: =B7*D7 -> 2.1638584 | G7: =B7*Assumptions!$B$21 -> 6.6635097
A8: gpt-5 (xhigh) | B8: =Table6!L8 -> 28.666084 | C8: =Assumptions!$B$9 -> 0.353 | D8: =Assumptions!$B$10 -> 0.0516 | E8: =B8*C8 -> 10.119128 | F8: =B8*D8 -> 1.4791699 | G8: =B8*Assumptions!$B$21 -> 4.5550408
A9: gpt-5.2 (non-reasoning) | B9: =Table6!L9 -> 7.8407841 | C9: =Assumptions!$B$9 -> 0.353 | D9: =Assumptions!$B$10 -> 0.0516 | E9: =B9*C9 -> 2.7677968 | F9: =B9*D9 -> 0.40458446 | G9: =B9*Assumptions!$B$21 -> 1.2459006
A10: gpt-5.2 (low) | B10: =Table6!L10 -> 13.724575 | C10: =Assumptions!$B$9 -> 0.353 | D10: =Assumptions!$B$10 -> 0.0516 | E10: =B10*C10 -> 4.844775 | F10: =B10*D10 -> 0.70818807 | G10: =B10*Assumptions!$B$21 -> 2.180835
A11: gpt-5.2 (medium) | B11: =Table6!L11 -> 15.05626 | C11: =Assumptions!$B$9 -> 0.353 | D11: =Assumptions!$B$10 -> 0.0516 | E11: =B11*C11 -> 5.3148596 | F11: =B11*D11 -> 0.77690299 | G11: =B11*Assumptions!$B$21 -> 2.3924396
A12: gpt-5.2 (high) | B12: =Table6!L12 -> 16.811745 | C12: =Assumptions!$B$9 -> 0.353 | D12: =Assumptions!$B$10 -> 0.0516 | E12: =B12*C12 -> 5.9345461 | F12: =B12*D12 -> 0.86748606 | G12: =B12*Assumptions!$B$21 -> 2.6713863
A13: gpt-5.2 (xhigh) | B13: =Table6!L13 -> 25.634176 | C13: =Assumptions!$B$9 -> 0.353 | D13: =Assumptions!$B$10 -> 0.0516 | E13: =B13*C13 -> 9.048864 | F13: =B13*D13 -> 1.3227235 | G13: =B13*Assumptions!$B$21 -> 4.0732705
A14: gpt-5.4-nano (non-reasoning) | B14: =Table6!L14 -> 3.0195381 | C14: =Assumptions!$B$9 -> 0.353 | D14: =Assumptions!$B$10 -> 0.0516 | E14: =B14*C14 -> 1.065897 | F14: =B14*D14 -> 0.15580817 | G14: =B14*Assumptions!$B$21 -> 0.47980461
... A49: gpt-5.6-terra (xhigh) | B49: =Table6!L49 -> 8.3417643 | C49: =Assumptions!$B$9 -> 0.353 | D49: =Assumptions!$B$10 -> 0.0516 | E49: =B49*C49 -> 2.9446428 | F49: =B49*D49 -> 0.43043504 | G49: =B49*Assumptions!$B$21 -> 1.3255063

Sheet C_Low
A1: Appendix C — staged low-range calculation (formulas). T and R bands are bootstrap percentile factors from the Bootstrap sheet (v1.0.0); A, PQPC and P are declared bounds (Assumptions).
A2: Model | B2: Adjusted Wh | C2: TPS Mean | D2: TPS SD | E2: Reasoning Mode | F2: Fixed_low | G2: TPS_low | H2: R_low | I2: Compounded | J2: Wh_low | K2: LB gCO2e/1,000 tokens | L2: MB gCO2e/1,000 tokens | M2: MB (procurement-lag) gCO2e/1,000 tokens
A3: gpt-4o-mini | B3: =Table6!L3 -> 2.0195 | C3: =Corpus!E3 -> 80.1 | D3: =Corpus!F3 -> 23.9 | E3: =Corpus!Q3 -> None | F3: =IF(Corpus!R3="5x",Assumptions!$B$17,Assumptions!$B$19) -> 0.4085 | G3: =Bootstrap!D3 -> 0.866 | H3: =IF(Corpus!Q3="None",1,Bootstrap!K3) -> 1 | I3: =F3*G3*H3 -> 0.353761 | J3: =B3*I3 -> 0.71442034 | K3: =J3*Assumptions!$B$9 -> 0.25219038 | L3: =J3*Assumptions!$B$10 -> 0.03686409 | M3: =J3*Assumptions!$B$21 -> 0.11352139
A4: gpt-5 (non-reasoning) | B4: =Table6!L4 -> 7.7788628 | C4: =Corpus!E4 -> 61.4 | D4: =Corpus!F4 -> 13.3 | E4: =Corpus!Q4 -> None | F4: =IF(Corpus!R4="5x",Assumptions!$B$17,Assumptions!$B$19) -> 0.216505 | G4: =Bootstrap!D4 -> 0.8867 | H4: =IF(Corpus!Q4="None",1,Bootstrap!K4) -> 1 | I4: =F4*G4*H4 -> 0.19197498 | J4: =B4*I4 -> 1.4933471 | K4: =J4*Assumptions!$B$9 -> 0.52715151 | L4: =J4*Assumptions!$B$10 -> 0.077056708 | M4: =J4*Assumptions!$B$21 -> 0.23729285
A5: gpt-5 (low) | B5: =Table6!L5 -> 17.284302 | C5: =Corpus!E5 -> 61.7 | D5: =Corpus!F5 -> 14.2 | E5: =Corpus!Q5 -> Low | F5: =IF(Corpus!R5="5x",Assumptions!$B$17,Assumptions!$B$19) -> 0.216505 | G5: =Bootstrap!D5 -> 0.8833 | H5: =IF(Corpus!Q5="None",1,Bootstrap!K5) -> 0.9725 | I5: =F5*G5*H5 -> 0.1859798 | J5: =B5*I5 -> 3.2145309 | K5: =J5*Assumptions!$B$9 -> 1.1347294 | L5: =J5*Assumptions!$B$10 -> 0.1658698 | M5: =J5*Assumptions!$B$21 -> 0.51078896
A6: gpt-5 (medium) | B6: =Table6!L6 -> 28.604841 | C6: =Corpus!E6 -> 60.8 | D6: =Corpus!F6 -> 14.5 | E6: =Corpus!Q6 -> Medium | F6: =IF(Corpus!R6="5x",Assumptions!$B$17,Assumptions!$B$19) -> 0.216505 | G6: =Bootstrap!D6 -> 0.8899 | H6: =IF(Corpus!Q6="None",1,Bootstrap!K6) -> 0.8875 | I6: =F6*G6*H6 -> 0.17099267 | J6: =B6*I6 -> 4.8912181 | K6: =J6*Assumptions!$B$9 -> 1.7266 | L6: =J6*Assumptions!$B$10 -> 0.25238686 | M6: =J6*Assumptions!$B$21 -> 0.77721456
A7: gpt-5 (high) | B7: =Table6!L7 -> 41.935241 | C7: =Corpus!E7 -> 68.1 | D7: =Corpus!F7 -> 15.7 | E7: =Corpus!Q7 -> High | F7: =IF(Corpus!R7="5x",Assumptions!$B$17,Assumptions!$B$19) -> 0.216505 | G7: =Bootstrap!D7 -> 0.8882 | H7: =IF(Corpus!Q7="None",1,Bootstrap!K7) -> 0.951 | I7: =F7*G7*H7 -> 0.18287705 | J7: =B7*I7 -> 7.6689933 | K7: =J7*Assumptions!$B$9 -> 2.7071546 | L7: =J7*Assumptions!$B$10 -> 0.39572005 | M7: =J7*Assumptions!$B$21 -> 1.218603
A8: gpt-5 (xhigh) | B8: =Table6!L8 -> 28.666084 | C8: =Corpus!E8 -> 63.8 | D8: =Corpus!F8 -> 16.7 | E8: =Corpus!Q8 -> xHigh | F8: =IF(Corpus!R8="5x",Assumptions!$B$17,Assumptions!$B$19) -> 0.216505 | G8: =Bootstrap!D8 -> 0.9 | H8: =IF(Corpus!Q8="None",1,Bootstrap!K8) -> 0.9429 | I8: =F8*G8*H8 -> 0.18372831 | J8: =B8*I8 -> 5.2667711 | K8: =J8*Assumptions!$B$9 -> 1.8591702 | L8: =J8*Assumptions!$B$10 -> 0.27176539 | M8: =J8*Assumptions!$B$21 -> 0.83688993
A9: gpt-5.2 (non-reasoning) | B9: =Table6!L9 -> 7.8407841 | C9: =Corpus!E9 -> 59.6 | D9: =Corpus!F9 -> 6.4 | E9: =Corpus!Q9 -> None | F9: =IF(Corpus!R9="5x",Assumptions!$B$17,Assumptions!$B$19) -> 0.216505 | G9: =Bootstrap!D9 -> 0.8907 | H9: =IF(Corpus!Q9="None",1,Bootstrap!K9) -> 1 | I9: =F9*G9*H9 -> 0.192841 | J9: =B9*I9 -> 1.5120247 | K9: =J9*Assumptions!$B$9 -> 0.53374471 | L9: =J9*Assumptions!$B$10 -> 0.078020473 | M9: =J9*Assumptions!$B$21 -> 0.24026072
A10: gpt-5.2 (low) | B10: =Table6!L10 -> 13.724575 | C10: =Corpus!E10 -> 57 | D10: =Corpus!F10 -> 6 | E10: =Corpus!Q10 -> Low | F10: =IF(Corpus!R10="5x",Assumptions!$B$17,Assumptions!$B$19) -> 0.216505 | G10: =Bootstrap!D10 -> 0.8991 | H10: =IF(Corpus!Q10="None",1,Bootstrap!K10) -> 0.9779 | I10: =F10*G10*H10 -> 0.19035767 | J10: =B10*I10 -> 2.6125781 | K10: =J10*Assumptions!$B$9 -> 0.92224006 | L10: =J10*Assumptions!$B$10 -> 0.13480903 | M10: =J10*Assumptions!$B$21 -> 0.41513866
A11: gpt-5.2 (medium) | B11: =Table6!L11 -> 15.05626 | C11: =Corpus!E11 -> 57.9 | D11: =Corpus!F11 -> 6.3 | E11: =Corpus!Q11 -> Medium | F11: =IF(Corpus!R11="5x",Assumptions!$B$17,Assumptions!$B$19) -> 0.216505 | G11: =Bootstrap!D11 -> 0.8998 | H11: =IF(Corpus!Q11="None",1,Bootstrap!K11) -> 0.9838 | I11: =F11*G11*H11 -> 0.19165526 | J11: =B11*I11 -> 2.8856113 | K11: =J11*Assumptions!$B$9 -> 1.0186208 | L11: =J11*Assumptions!$B$10 -> 0.14889754 | M11: =J11*Assumptions!$B$21 -> 0.45852364
A12: gpt-5.2 (high) | B12: =Table6!L12 -> 16.811745 | C12: =Corpus!E12 -> 57.5 | D12: =Corpus!F12 -> 6.4 | E12: =Corpus!Q12 -> High | F12: =IF(Corpus!R12="5x",Assumptions!$B$17,Assumptions!$B$19) -> 0.216505 | G12: =Bootstrap!D12 -> 0.8995 | H12: =IF(Corpus!Q12="None",1,Bootstrap!K12) -> 0.9646 | I12: =F12*G12*H12 -> 0.18785223 | J12: =B12*I12 -> 3.1581239 | K12: =J12*Assumptions!$B$9 -> 1.1148177 | L12: =J12*Assumptions!$B$10 -> 0.16295919 | M12: =J12*Assumptions!$B$21 -> 0.50182588
A13: gpt-5.2 (xhigh) | B13: =Table6!L13 -> 25.634176 | C13: =Corpus!E13 -> 59.1 | D13: =Corpus!F13 -> 6.9 | E13: =Corpus!Q13 -> xHigh | F13: =IF(Corpus!R13="5x",Assumptions!$B$17,Assumptions!$B$19) -> 0.216505 | G13: =Bootstrap!D13 -> 0.9016 | H13: =IF(Corpus!Q13="None",1,Bootstrap!K13) -> 0.9268 | I13: =F13*G13*H13 -> 0.1809122 | J13: =B13*I13 -> 4.6375351 | K13: =J13*Assumptions!$B$9 -> 1.6370499 | L13: =J13*Assumptions!$B$10 -> 0.23929681 | M13: =J13*Assumptions!$B$21 -> 0.73690433
A14: gpt-5.4-nano (non-reasoning) | B14: =Table6!L14 -> 3.0195381 | C14: =Corpus!E14 -> 156.6 | D14: =Corpus!F14 -> 18.7 | E14: =Corpus!Q14 -> None | F14: =IF(Corpus!R14="5x",Assumptions!$B$17,Assumptions!$B$19) -> 0.216505 | G14: =Bootstrap!D14 -> 0.8914 | H14: =IF(Corpus!Q14="None",1,Bootstrap!K14) -> 1 | I14: =F14*G14*H14 -> 0.19299256 | J14: =B14*I14 -> 0.58274839 | K14: =J14*Assumptions!$B$9 -> 0.20571018 | L14: =J14*Assumptions!$B$10 -> 0.030069817 | M14: =J14*Assumptions!$B$21 -> 0.092598719
... A49: gpt-5.6-terra (xhigh) | B49: =Table6!L49 -> 8.3417643 | C49: =Corpus!E49 -> 94.7 | D49: =Corpus!F49 -> 8.4 | E49: =Corpus!Q49 -> xHigh | F49: =IF(Corpus!R49="5x",Assumptions!$B$17,Assumptions!$B$19) -> 0.216505 | G49: =Bootstrap!D49 -> 0.8917 | H49: =IF(Corpus!Q49="None",1,Bootstrap!K49) -> 0.9746 | I49: =F49*G49*H49 -> 0.18815385 | J49: =B49*I49 -> 1.569535 | K49: =J49*Assumptions!$B$9 -> 0.55404587 | L49: =J49*Assumptions!$B$10 -> 0.080988008 | M49: =J49*Assumptions!$B$21 -> 0.24939912

Sheet C_High
A1: Appendix C — staged high-range calculation (formulas). T and R bands are bootstrap percentile factors from the Bootstrap sheet (v1.0.0); A, PQPC and P are declared bounds (Assumptions).
A2: Model | B2: Adjusted Wh | C2: TPS Mean | D2: TPS SD | E2: Reasoning Mode | F2: Fixed_high | G2: TPS_high | H2: R_high | I2: Compounded | J2: Wh_high | K2: LB gCO2e/1,000 tokens | L2: MB gCO2e/1,000 tokens | M2: MB (procurement-lag) gCO2e/1,000 tokens
A3: gpt-4o-mini | B3: =Table6!L3 -> 2.0195 | C3: =Corpus!E3 -> 80.1 | D3: =Corpus!F3 -> 23.9 | E3: =Corpus!Q3 -> None | F3: =IF(Corpus!R3="5x",Assumptions!$B$18,Assumptions!$B$20) -> 1.236 | G3: =Bootstrap!E3 -> 1.1563 | H3: =IF(Corpus!Q3="None",1,Bootstrap!L3) -> 1 | I3: =F3*G3*H3 -> 1.4291868 | J3: =B3*I3 -> 2.8862427 | K3: =J3*Assumptions!$B$9 -> 1.0188437 | L3: =J3*Assumptions!$B$10 -> 0.14893013 | M3: =J3*Assumptions!$B$21 -> 0.45862397
A4: gpt-5 (non-reasoning) | B4: =Table6!L4 -> 7.7788628 | C4: =Corpus!E4 -> 61.4 | D4: =Corpus!F4 -> 13.3 | E4: =Corpus!Q4 -> None | F4: =IF(Corpus!R4="5x",Assumptions!$B$18,Assumptions!$B$20) -> 1.82928 | G4: =Bootstrap!E4 -> 1.1253 | H4: =IF(Corpus!Q4="None",1,Bootstrap!L4) -> 1 | I4: =F4*G4*H4 -> 2.0584888 | J4: =B4*I4 -> 16.012702 | K4: =J4*Assumptions!$B$9 -> 5.6524838 | L4: =J4*Assumptions!$B$10 -> 0.82625542 | M4: =J4*Assumptions!$B$21 -> 2.5444183
A5: gpt-5 (low) | B5: =Table6!L5 -> 17.284302 | C5: =Corpus!E5 -> 61.7 | D5: =Corpus!F5 -> 14.2 | E5: =Corpus!Q5 -> Low | F5: =IF(Corpus!R5="5x",Assumptions!$B$18,Assumptions!$B$20) -> 1.82928 | G5: =Bootstrap!E5 -> 1.1249 | H5: =IF(Corpus!Q5="None",1,Bootstrap!L5) -> 1.0356 | I5: =F5*G5*H5 -> 2.1310132 | J5: =B5*I5 -> 36.833075 | K5: =J5*Assumptions!$B$9 -> 13.002076 | L5: =J5*Assumptions!$B$10 -> 1.9005867 | M5: =J5*Assumptions!$B$21 -> 5.8527757
A6: gpt-5 (medium) | B6: =Table6!L6 -> 28.604841 | C6: =Corpus!E6 -> 60.8 | D6: =Corpus!F6 -> 14.5 | E6: =Corpus!Q6 -> Medium | F6: =IF(Corpus!R6="5x",Assumptions!$B$18,Assumptions!$B$20) -> 1.82928 | G6: =Bootstrap!E6 -> 1.1299 | H6: =IF(Corpus!Q6="None",1,Bootstrap!L6) -> 1.046 | I6: =F6*G6*H6 -> 2.161981 | J6: =B6*I6 -> 61.843123 | K6: =J6*Assumptions!$B$9 -> 21.830622 | L6: =J6*Assumptions!$B$10 -> 3.1911052 | M6: =J6*Assumptions!$B$21 -> 9.8268723
A7: gpt-5 (high) | B7: =Table6!L7 -> 41.935241 | C7: =Corpus!E7 -> 68.1 | D7: =Corpus!F7 -> 15.7 | E7: =Corpus!Q7 -> High | F7: =IF(Corpus!R7="5x",Assumptions!$B$18,Assumptions!$B$20) -> 1.82928 | G7: =Bootstrap!E7 -> 1.1202 | H7: =IF(Corpus!Q7="None",1,Bootstrap!L7) -> 1.0593 | I7: =F7*G7*H7 -> 2.1706746 | J7: =B7*I7 -> 91.027762 | K7: =J7*Assumptions!$B$9 -> 32.1328 | L7: =J7*Assumptions!$B$10 -> 4.6970325 | M7: =J7*Assumptions!$B$21 -> 14.464311
A8: gpt-5 (xhigh) | B8: =Table6!L8 -> 28.666084 | C8: =Corpus!E8 -> 63.8 | D8: =Corpus!F8 -> 16.7 | E8: =Corpus!Q8 -> xHigh | F8: =IF(Corpus!R8="5x",Assumptions!$B$18,Assumptions!$B$20) -> 1.82928 | G8: =Bootstrap!E8 -> 1.1394 | H8: =IF(Corpus!Q8="None",1,Bootstrap!L8) -> 1.079 | I8: =F8*G8*H8 -> 2.2489399 | J8: =B8*I8 -> 64.4683 | K8: =J8*Assumptions!$B$9 -> 22.75731 | L8: =J8*Assumptions!$B$10 -> 3.3265643 | M8: =J8*Assumptions!$B$21 -> 10.244013
A9: gpt-5.2 (non-reasoning) | B9: =Table6!L9 -> 7.8407841 | C9: =Corpus!E9 -> 59.6 | D9: =Corpus!F9 -> 6.4 | E9: =Corpus!Q9 -> None | F9: =IF(Corpus!R9="5x",Assumptions!$B$18,Assumptions!$B$20) -> 1.82928 | G9: =Bootstrap!E9 -> 1.1051 | H9: =IF(Corpus!Q9="None",1,Bootstrap!L9) -> 1 | I9: =F9*G9*H9 -> 2.0215373 | J9: =B9*I9 -> 15.850438 | K9: =J9*Assumptions!$B$9 -> 5.5952045 | L9: =J9*Assumptions!$B$10 -> 0.81788259 | M9: =J9*Assumptions!$B$21 -> 2.5186346
A10: gpt-5.2 (low) | B10: =Table6!L10 -> 13.724575 | C10: =Corpus!E10 -> 57 | D10: =Corpus!F10 -> 6 | E10: =Corpus!Q10 -> Low | F10: =IF(Corpus!R10="5x",Assumptions!$B$18,Assumptions!$B$20) -> 1.82928 | G10: =Bootstrap!E10 -> 1.1179 | H10: =IF(Corpus!Q10="None",1,Bootstrap!L10) -> 1.0318 | I10: =F10*G10*H10 -> 2.1099816 | J10: =B10*I10 -> 28.958601 | K10: =J10*Assumptions!$B$9 -> 10.222386 | L10: =J10*Assumptions!$B$10 -> 1.4942638 | M10: =J10*Assumptions!$B$21 -> 4.6015216
A11: gpt-5.2 (medium) | B11: =Table6!L11 -> 15.05626 | C11: =Corpus!E11 -> 57.9 | D11: =Corpus!F11 -> 6.3 | E11: =Corpus!Q11 -> Medium | F11: =IF(Corpus!R11="5x",Assumptions!$B$18,Assumptions!$B$20) -> 1.82928 | G11: =Bootstrap!E11 -> 1.1139 | H11: =IF(Corpus!Q11="None",1,Bootstrap!L11) -> 1.0163 | I11: =F11*G11*H11 -> 2.0708484 | J11: =B11*I11 -> 31.179232 | K11: =J11*Assumptions!$B$9 -> 11.006269 | L11: =J11*Assumptions!$B$10 -> 1.6088484 | M11: =J11*Assumptions!$B$21 -> 4.9543799
A12: gpt-5.2 (high) | B12: =Table6!L12 -> 16.811745 | C12: =Corpus!E12 -> 57.5 | D12: =Corpus!F12 -> 6.4 | E12: =Corpus!Q12 -> High | F12: =IF(Corpus!R12="5x",Assumptions!$B$18,Assumptions!$B$20) -> 1.82928 | G12: =Bootstrap!E12 -> 1.101 | H12: =IF(Corpus!Q12="None",1,Bootstrap!L12) -> 1.0078 | I12: =F12*G12*H12 -> 2.0297468 | J12: =B12*I12 -> 34.123586 | K12: =J12*Assumptions!$B$9 -> 12.045626 | L12: =J12*Assumptions!$B$10 -> 1.760777 | M12: =J12*Assumptions!$B$21 -> 5.4222378
A13: gpt-5.2 (xhigh) | B13: =Table6!L13 -> 25.634176 | C13: =Corpus!E13 -> 59.1 | D13: =Corpus!F13 -> 6.9 | E13: =Corpus!Q13 -> xHigh | F13: =IF(Corpus!R13="5x",Assumptions!$B$18,Assumptions!$B$20) -> 1.82928 | G13: =Bootstrap!E13 -> 1.1161 | H13: =IF(Corpus!Q13="None",1,Bootstrap!L13) -> 1.0231 | I13: =F13*G13*H13 -> 2.0888217 | J13: =B13*I13 -> 53.545223 | K13: =J13*Assumptions!$B$9 -> 18.901464 | L13: =J13*Assumptions!$B$10 -> 2.7629335 | M13: =J13*Assumptions!$B$21 -> 8.508336
A14: gpt-5.4-nano (non-reasoning) | B14: =Table6!L14 -> 3.0195381 | C14: =Corpus!E14 -> 156.6 | D14: =Corpus!F14 -> 18.7 | E14: =Corpus!Q14 -> None | F14: =IF(Corpus!R14="5x",Assumptions!$B$18,Assumptions!$B$20) -> 1.82928 | G14: =Bootstrap!E14 -> 1.114 | H14: =IF(Corpus!Q14="None",1,Bootstrap!L14) -> 1 | I14: =F14*G14*H14 -> 2.0378179 | J14: =B14*I14 -> 6.1532689 | K14: =J14*Assumptions!$B$9 -> 2.1721039 | L14: =J14*Assumptions!$B$10 -> 0.31750868 | M14: =J14*Assumptions!$B$21 -> 0.97775443
... A49: gpt-5.6-terra (xhigh) | B49: =Table6!L49 -> 8.3417643 | C49: =Corpus!E49 -> 94.7 | D49: =Corpus!F49 -> 8.4 | E49: =Corpus!Q49 -> xHigh | F49: =IF(Corpus!R49="5x",Assumptions!$B$18,Assumptions!$B$20) -> 1.82928 | G49: =Bootstrap!E49 -> 1.1072 | H49: =IF(Corpus!Q49="None",1,Bootstrap!L49) -> 1.0229 | I49: =F49*G49*H49 -> 2.07176 | J49: =B49*I49 -> 17.282133 | K49: =J49*Assumptions!$B$9 -> 6.1005931 | L49: =J49*Assumptions!$B$10 -> 0.89175809 | M49: =J49*Assumptions!$B$21 -> 2.746131

Sheet Table8
A1: Table 8 — uncertainty bounds (links to C_Low / C_High and Table 7). Columns H-J: market-based bounds under the procurement-lag crediting scenario (Section 4.8).
A2: Model | B2: LB Low | C2: LB Central | D2: LB High | E2: MB Low | F2: MB Central | G2: MB High | H2: MB-lag Low | I2: MB-lag Central | J2: MB-lag High
A3: gpt-4o-mini | B3: =C_Low!K3 -> 0.25219038 | C3: =Table7!E3 -> 0.7128835 | D3: =C_High!K3 -> 1.0188437 | E3: =C_Low!L3 -> 0.03686409 | F3: =Table7!F3 -> 0.1042062 | G3: =C_High!L3 -> 0.14893013 | H3: =C_Low!M3 -> 0.11352139 | I3: =Table7!G3 -> 0.32089855 | J3: =C_High!M3 -> 0.45862397
A4: gpt-5 (non-reasoning) | B4: =C_Low!K4 -> 0.52715151 | C4: =Table7!E4 -> 2.7459386 | D4: =C_High!K4 -> 5.6524838 | E4: =C_Low!L4 -> 0.077056708 | F4: =Table7!F4 -> 0.40138932 | G4: =C_High!L4 -> 0.82625542 | H4: =C_Low!M4 -> 0.23729285 | I4: =Table7!G4 -> 1.2360613 | J4: =C_High!M4 -> 2.5444183
A5: gpt-5 (low) | B5: =C_Low!K5 -> 1.1347294 | C5: =Table7!E5 -> 6.1013585 | D5: =C_High!K5 -> 13.002076 | E5: =C_Low!L5 -> 0.1658698 | F5: =Table7!F5 -> 0.89186996 | G5: =C_High!L5 -> 1.9005867 | H5: =C_Low!M5 -> 0.51078896 | I5: =Table7!G5 -> 2.7464755 | J5: =C_High!M5 -> 5.8527757
A6: gpt-5 (medium) | B6: =C_Low!K6 -> 1.7266 | C6: =Table7!E6 -> 10.097509 | D6: =C_High!K6 -> 21.830622 | E6: =C_Low!L6 -> 0.25238686 | F6: =Table7!F6 -> 1.4760098 | G6: =C_High!L6 -> 3.1911052 | H6: =C_Low!M6 -> 0.77721456 | I6: =Table7!G6 -> 4.5453092 | J6: =C_High!M6 -> 9.8268723
A7: gpt-5 (high) | B7: =C_Low!K7 -> 2.7071546 | C7: =Table7!E7 -> 14.80314 | D7: =C_High!K7 -> 32.1328 | E7: =C_Low!L7 -> 0.39572005 | F7: =Table7!F7 -> 2.1638584 | G7: =C_High!L7 -> 4.6970325 | H7: =C_Low!M7 -> 1.218603 | I7: =Table7!G7 -> 6.6635097 | J7: =C_High!M7 -> 14.464311
A8: gpt-5 (xhigh) | B8: =C_Low!K8 -> 1.8591702 | C8: =Table7!E8 -> 10.119128 | D8: =C_High!K8 -> 22.75731 | E8: =C_Low!L8 -> 0.27176539 | F8: =Table7!F8 -> 1.4791699 | G8: =C_High!L8 -> 3.3265643 | H8: =C_Low!M8 -> 0.83688993 | I8: =Table7!G8 -> 4.5550408 | J8: =C_High!M8 -> 10.244013
A9: gpt-5.2 (non-reasoning) | B9: =C_Low!K9 -> 0.53374471 | C9: =Table7!E9 -> 2.7677968 | D9: =C_High!K9 -> 5.5952045 | E9: =C_Low!L9 -> 0.078020473 | F9: =Table7!F9 -> 0.40458446 | G9: =C_High!L9 -> 0.81788259 | H9: =C_Low!M9 -> 0.24026072 | I9: =Table7!G9 -> 1.2459006 | J9: =C_High!M9 -> 2.5186346
A10: gpt-5.2 (low) | B10: =C_Low!K10 -> 0.92224006 | C10: =Table7!E10 -> 4.844775 | D10: =C_High!K10 -> 10.222386 | E10: =C_Low!L10 -> 0.13480903 | F10: =Table7!F10 -> 0.70818807 | G10: =C_High!L10 -> 1.4942638 | H10: =C_Low!M10 -> 0.41513866 | I10: =Table7!G10 -> 2.180835 | J10: =C_High!M10 -> 4.6015216
A11: gpt-5.2 (medium) | B11: =C_Low!K11 -> 1.0186208 | C11: =Table7!E11 -> 5.3148596 | D11: =C_High!K11 -> 11.006269 | E11: =C_Low!L11 -> 0.14889754 | F11: =Table7!F11 -> 0.77690299 | G11: =C_High!L11 -> 1.6088484 | H11: =C_Low!M11 -> 0.45852364 | I11: =Table7!G11 -> 2.3924396 | J11: =C_High!M11 -> 4.9543799
A12: gpt-5.2 (high) | B12: =C_Low!K12 -> 1.1148177 | C12: =Table7!E12 -> 5.9345461 | D12: =C_High!K12 -> 12.045626 | E12: =C_Low!L12 -> 0.16295919 | F12: =Table7!F12 -> 0.86748606 | G12: =C_High!L12 -> 1.760777 | H12: =C_Low!M12 -> 0.50182588 | I12: =Table7!G12 -> 2.6713863 | J12: =C_High!M12 -> 5.4222378
A13: gpt-5.2 (xhigh) | B13: =C_Low!K13 -> 1.6370499 | C13: =Table7!E13 -> 9.048864 | D13: =C_High!K13 -> 18.901464 | E13: =C_Low!L13 -> 0.23929681 | F13: =Table7!F13 -> 1.3227235 | G13: =C_High!L13 -> 2.7629335 | H13: =C_Low!M13 -> 0.73690433 | I13: =Table7!G13 -> 4.0732705 | J13: =C_High!M13 -> 8.508336
A14: gpt-5.4-nano (non-reasoning) | B14: =C_Low!K14 -> 0.20571018 | C14: =Table7!E14 -> 1.065897 | D14: =C_High!K14 -> 2.1721039 | E14: =C_Low!L14 -> 0.030069817 | F14: =Table7!F14 -> 0.15580817 | G14: =C_High!L14 -> 0.31750868 | H14: =C_Low!M14 -> 0.092598719 | I14: =Table7!G14 -> 0.47980461 | J14: =C_High!M14 -> 0.97775443
... A49: gpt-5.6-terra (xhigh) | B49: =C_Low!K49 -> 0.55404587 | C49: =Table7!E49 -> 2.9446428 | D49: =C_High!K49 -> 6.1005931 | E49: =C_Low!L49 -> 0.080988008 | F49: =Table7!F49 -> 0.43043504 | G49: =C_High!L49 -> 0.89175809 | H49: =C_Low!M49 -> 0.24939912 | I49: =Table7!G49 -> 1.3255063 | J49: =C_High!M49 -> 2.746131

Sheet T1_GPT55_Grid
A1: Table 1 — GPT-5.5 measured reasoning-mode multipliers: difficulty x length grid (medians, v2 fixed-task records, frozen corpus).
A2: Mode | B2: Hard-short (100/300) | C2: n | D2: Hard-medium (1k/1k) | E2: n | F2: Hard-long (10k/1.5k) | G2: n | H2: Easy floor (10k summarise) | I2: Heavy task k=36 (1k) | J2: n
A3: Minimal | B3: 2.07 | C3: 37 | D3: 1.71 | E3: 39 | F3: 1.84 | G3: 4 | H3: 1.02 | I3: 5.82 | J3: 12
A4: Low | B4: 1.64 | C4: 37 | D4: 1.45 | E4: 39 | F4: 1.34 | G4: 4 | H4: 1.01 | I4: 2.07 | J4: 20
A5: Medium | B5: 2.01 | C5: 37 | D5: 1.69 | E5: 39 | F5: 1.54 | G5: 4 | H5: 1.02 | I5: 3.21 | J5: 12
A6: High | B6: 2.99 | C6: 36 | D6: 2.39 | E6: 39 | F6: 2.2 | G6: 4 | H6: 1.14 | I6: 4.93 | J6: 12
A7: Xhigh | B7: 3.52 | C7: 37 | D7: 2.46 | E7: 38 | F7: 2.76 | G7: 3 | H7: 1.29 | I7: 5.62 | J7: 12
A9: Hard-long cells carry small n (2-4): reported with that caveat. Heavy task (36-element puzzle, added 30 Jul) is the task-demand sensitivity: reported separately, NOT compounded into Table 8 bands. | C9: 0 | E9: 0 | G9: 0 | J9: 0

Sheet TableB1
A1: Table B1 — OpenAI TPS summary, daily medians pooled per calendar day, full campaign 24 Jun - 22 Aug 2026.
A2: Model variant | B2: Mean visible TPS (o200k, daily medians) | C2: SD | D2: Days (n)
A3: gpt-4o-mini | B3: 80.1 | C3: 23.9 | D3: 57
A4: gpt-5 (high) | B4: 68.1 | C4: 15.7 | D4: 56
A5: gpt-5 (low) | B5: 61.7 | C5: 14.2 | D5: 57
A6: gpt-5 (medium) | B6: 60.8 | C6: 14.5 | D6: 57
A7: gpt-5 (minimal) | B7: 61.4 | C7: 13.3 | D7: 57
A8: gpt-5 (xhigh) | B8: 63.8 | C8: 16.7 | D8: 56
A9: gpt-5.2 (high) | B9: 57.5 | C9: 6.4 | D9: 56
A10: gpt-5.2 (low) | B10: 57 | C10: 6 | D10: 57
A11: gpt-5.2 (medium) | B11: 57.9 | C11: 6.3 | D11: 57
A12: gpt-5.2 (minimal) | B12: 59.6 | C12: 6.4 | D12: 57
A13: gpt-5.2 (xhigh) | B13: 59.1 | C13: 6.9 | D13: 56
A14: gpt-5.4 (high) | B14: 93.4 | C14: 11.3 | D14: 56
... A48: gpt-5.6-terra (xhigh) | B48: 94.7 | C48: 8.4 | D48: 40
A50: Mean SD across variants = 13.4. Variants with fewer than 8 collection days excluded (legacy gpt-5-mini/nano/5.1).

Sheet Levers
A1: Envelope log-factor report (Section 3.8 / after Table 8): ln(high/low) per factor, live formulas (v1.0.0). Larger = wider contribution. Total = sum; envelope ratio = exp(total).
A2: Model | B2: ln A span | C2: ln PQPC span | D2: ln P span | E2: ln T span | F2: ln R span | G2: Total log-width | H2: Envelope ratio (top/bottom)
A3: gpt-4o-mini | B3: =LN(Assumptions!$B$12/Assumptions!$B$11) -> 1.0262916 | C3: =IF(Corpus!R3="5x",LN(Assumptions!$B$14/Assumptions!$B$13),0) -> 0 | D3: =LN(Assumptions!$B$16/Assumptions!$B$15) -> 0.080852097 | E3: =LN(Bootstrap!E3/Bootstrap!D3) -> 0.28909562 | F3: =IF(Corpus!Q3="None",0,LN(Bootstrap!L3/Bootstrap!K3)) -> 0 | G3: =SUM(B3:F3) -> 1.3962393 | H3: =EXP(G3) -> 4.0399784
A4: gpt-5 (non-reasoning) | B4: =LN(Assumptions!$B$12/Assumptions!$B$11) -> 1.0262916 | C4: =IF(Corpus!R4="5x",LN(Assumptions!$B$14/Assumptions!$B$13),0) -> 1.0269204 | D4: =LN(Assumptions!$B$16/Assumptions!$B$15) -> 0.080852097 | E4: =LN(Bootstrap!E4/Bootstrap!D4) -> 0.23829824 | F4: =IF(Corpus!Q4="None",0,LN(Bootstrap!L4/Bootstrap!K4)) -> 0 | G4: =SUM(B4:F4) -> 2.3723623 | H4: =EXP(G4) -> 10.722693
A5: gpt-5 (low) | B5: =LN(Assumptions!$B$12/Assumptions!$B$11) -> 1.0262916 | C5: =IF(Corpus!R5="5x",LN(Assumptions!$B$14/Assumptions!$B$13),0) -> 1.0269204 | D5: =LN(Assumptions!$B$16/Assumptions!$B$15) -> 0.080852097 | E5: =LN(Bootstrap!E5/Bootstrap!D5) -> 0.24178453 | F5: =IF(Corpus!Q5="None",0,LN(Bootstrap!L5/Bootstrap!K5)) -> 0.062866172 | G5: =SUM(B5:F5) -> 2.4387148 | H5: =EXP(G5) -> 11.458305
A6: gpt-5 (medium) | B6: =LN(Assumptions!$B$12/Assumptions!$B$11) -> 1.0262916 | C6: =IF(Corpus!R6="5x",LN(Assumptions!$B$14/Assumptions!$B$13),0) -> 1.0269204 | D6: =LN(Assumptions!$B$16/Assumptions!$B$15) -> 0.080852097 | E6: =LN(Bootstrap!E6/Bootstrap!D6) -> 0.23877532 | F6: =IF(Corpus!Q6="None",0,LN(Bootstrap!L6/Bootstrap!K6)) -> 0.16432012 | G6: =SUM(B6:F6) -> 2.5371595 | H6: =EXP(G6) -> 12.643706
A7: gpt-5 (high) | B7: =LN(Assumptions!$B$12/Assumptions!$B$11) -> 1.0262916 | C7: =IF(Corpus!R7="5x",LN(Assumptions!$B$14/Assumptions!$B$13),0) -> 1.0269204 | D7: =LN(Assumptions!$B$16/Assumptions!$B$15) -> 0.080852097 | E7: =LN(Bootstrap!E7/Bootstrap!D7) -> 0.23206558 | F7: =IF(Corpus!Q7="None",0,LN(Bootstrap!L7/Bootstrap!K7)) -> 0.10784953 | G7: =SUM(B7:F7) -> 2.4739792 | H7: =EXP(G7) -> 11.869584
A8: gpt-5 (xhigh) | B8: =LN(Assumptions!$B$12/Assumptions!$B$11) -> 1.0262916 | C8: =IF(Corpus!R8="5x",LN(Assumptions!$B$14/Assumptions!$B$13),0) -> 1.0269204 | D8: =LN(Assumptions!$B$16/Assumptions!$B$15) -> 0.080852097 | E8: =LN(Bootstrap!E8/Bootstrap!D8) -> 0.23586232 | F8: =IF(Corpus!Q8="None",0,LN(Bootstrap!L8/Bootstrap!K8)) -> 0.13482973 | G8: =SUM(B8:F8) -> 2.5047561 | H8: =EXP(G8) -> 12.240574
A9: gpt-5.2 (non-reasoning) | B9: =LN(Assumptions!$B$12/Assumptions!$B$11) -> 1.0262916 | C9: =IF(Corpus!R9="5x",LN(Assumptions!$B$14/Assumptions!$B$13),0) -> 1.0269204 | D9: =LN(Assumptions!$B$16/Assumptions!$B$15) -> 0.080852097 | E9: =LN(Bootstrap!E9/Bootstrap!D9) -> 0.21568344 | F9: =IF(Corpus!Q9="None",0,LN(Bootstrap!L9/Bootstrap!K9)) -> 0 | G9: =SUM(B9:F9) -> 2.3497475 | H9: =EXP(G9) -> 10.482923
A10: gpt-5.2 (low) | B10: =LN(Assumptions!$B$12/Assumptions!$B$11) -> 1.0262916 | C10: =IF(Corpus!R10="5x",LN(Assumptions!$B$14/Assumptions!$B$13),0) -> 1.0269204 | D10: =LN(Assumptions!$B$16/Assumptions!$B$15) -> 0.080852097 | E10: =LN(Bootstrap!E10/Bootstrap!D10) -> 0.21781294 | F10: =IF(Corpus!Q10="None",0,LN(Bootstrap!L10/Bootstrap!K10)) -> 0.053652713 | G10: =SUM(B10:F10) -> 2.4055297 | H10: =EXP(G10) -> 11.084301
A11: gpt-5.2 (medium) | B11: =LN(Assumptions!$B$12/Assumptions!$B$11) -> 1.0262916 | C11: =IF(Corpus!R11="5x",LN(Assumptions!$B$14/Assumptions!$B$13),0) -> 1.0269204 | D11: =LN(Assumptions!$B$16/Assumptions!$B$15) -> 0.080852097 | E11: =LN(Bootstrap!E11/Bootstrap!D11) -> 0.21345013 | F11: =IF(Corpus!Q11="None",0,LN(Bootstrap!L11/Bootstrap!K11)) -> 0.032501236 | G11: =SUM(B11:F11) -> 2.3800155 | H11: =EXP(G11) -> 10.80507
A12: gpt-5.2 (high) | B12: =LN(Assumptions!$B$12/Assumptions!$B$11) -> 1.0262916 | C12: =IF(Corpus!R12="5x",LN(Assumptions!$B$14/Assumptions!$B$13),0) -> 1.0269204 | D12: =LN(Assumptions!$B$16/Assumptions!$B$15) -> 0.080852097 | E12: =LN(Bootstrap!E12/Bootstrap!D12) -> 0.20213508 | F12: =IF(Corpus!Q12="None",0,LN(Bootstrap!L12/Bootstrap!K12)) -> 0.043811509 | G12: =SUM(B12:F12) -> 2.3800107 | H12: =EXP(G12) -> 10.805018
A13: gpt-5.2 (xhigh) | B13: =LN(Assumptions!$B$12/Assumptions!$B$11) -> 1.0262916 | C13: =IF(Corpus!R13="5x",LN(Assumptions!$B$14/Assumptions!$B$13),0) -> 1.0269204 | D13: =LN(Assumptions!$B$16/Assumptions!$B$15) -> 0.080852097 | E13: =LN(Bootstrap!E13/Bootstrap!D13) -> 0.21342478 | F13: =IF(Corpus!Q13="None",0,LN(Bootstrap!L13/Bootstrap!K13)) -> 0.09885472 | G13: =SUM(B13:F13) -> 2.4463436 | H13: =EXP(G13) -> 11.546052
A14: gpt-5.4-nano (non-reasoning) | B14: =LN(Assumptions!$B$12/Assumptions!$B$11) -> 1.0262916 | C14: =IF(Corpus!R14="5x",LN(Assumptions!$B$14/Assumptions!$B$13),0) -> 1.0269204 | D14: =LN(Assumptions!$B$16/Assumptions!$B$15) -> 0.080852097 | E14: =LN(Bootstrap!E14/Bootstrap!D14) -> 0.22291916 | F14: =IF(Corpus!Q14="None",0,LN(Bootstrap!L14/Bootstrap!K14)) -> 0 | G14: =SUM(B14:F14) -> 2.3569832 | H14: =EXP(G14) -> 10.559049
... A49: gpt-5.6-terra (xhigh) | B49: =LN(Assumptions!$B$12/Assumptions!$B$11) -> 1.0262916 | C49: =IF(Corpus!R49="5x",LN(Assumptions!$B$14/Assumptions!$B$13),0) -> 1.0269204 | D49: =LN(Assumptions!$B$16/Assumptions!$B$15) -> 0.080852097 | E49: =LN(Bootstrap!E49/Bootstrap!D49) -> 0.21645983 | F49: =IF(Corpus!Q49="None",0,LN(Bootstrap!L49/Bootstrap!K49)) -> 0.048369879 | G49: =SUM(B49:F49) -> 2.3988938 | H49: =EXP(G49) -> 11.010989
A51: Means across GPT-5.x reasoning variants (Corpus mode <> None, PQPC class 5x): | B51: =AVERAGEIFS(B3:B49,Corpus!$Q$3:$Q$49,"<>None",Corpus!$R$3:$R$49,"5x") -> 1.0262916 | C51: =AVERAGEIFS(C3:C49,Corpus!$Q$3:$Q$49,"<>None",Corpus!$R$3:$R$49,"5x") -> 1.0269204 | D51: =AVERAGEIFS(D3:D49,Corpus!$Q$3:$Q$49,"<>None",Corpus!$R$3:$R$49,"5x") -> 0.080852097 | E51: =AVERAGEIFS(E3:E49,Corpus!$Q$3:$Q$49,"<>None",Corpus!$R$3:$R$49,"5x") -> 0.22574733 | F51: =AVERAGEIFS(F3:F49,Corpus!$Q$3:$Q$49,"<>None",Corpus!$R$3:$R$49,"5x") -> 0.07594181 | G51: =AVERAGEIFS(G3:G49,Corpus!$Q$3:$Q$49,"<>None",Corpus!$R$3:$R$49,"5x") -> 2.4357532 | H51: =AVERAGEIFS(H3:H49,Corpus!$Q$3:$Q$49,"<>None",Corpus!$R$3:$R$49,"5x") -> 11.479747
A52: Medians across all 47 rows: | B52: =MEDIAN(B3:B49) -> 1.0262916 | C52: =MEDIAN(C3:C49) -> 1.0269204 | D52: =MEDIAN(D3:D49) -> 0.080852097 | E52: =MEDIAN(E3:E49) -> 0.22459485 | F52: =MEDIAN(F3:F49) -> 0.041847938 | G52: =MEDIAN(G3:G49) -> 2.3988938 | H52: =MEDIAN(H3:H49) -> 11.010989
A53: Envelope ratio, median across GPT-5.x reasoning variants: | H53: =EXP(G51) -> 11.424421
E55: =MIN(E3:E49) -> 0.20213508 | F55: =MIN(F3:F49) -> 0
E56: =MAX(E3:E49) -> 0.32822836 | F56: =MAX(F3:F49) -> 0.47685335

Sheet Bootstrap
A1: Bootstrap bands (v1.0.0). T: anchor/model ratio of medians of daily-median TPS (10k workload), days resampled independently for anchor and model, B = 10,000, seed 20260822; bounds = 5th/95th percentile of the ratio divided by the point ratio. R: requests in the hard-task 1k cell (prompt_version 2, k = 12) resampled, B = 10,000; bounds = 5th/95th percentile of the cell median divided by the point median. Non-reasoning variants: R = 1, no band. Relative factors apply to the Corpus-sheet centrals.
A2: Row label | B2: Corpus label | C2: days | D2: T_low (boot) | E2: T_high (boot) | F2: T_low (mean/(mean+SD) method, comparison only) | G2: T_high (mean ± SD method, comparison only) | H2: fraction of days outside mean±1SD | I2: R cell n | J2: R cell median | K2: R_low (boot) | L2: R_high (boot) | M2: R_low (floor/central, comparison only) | N2: R_high (short/central, comparison only)
A3: gpt-4o-mini | B3: gpt-4o-mini | C3: 57 | D3: 0.866 | E3: 1.1563 | F3: =Corpus!E3/(Corpus!E3+Corpus!F3) -> 0.77019231 | G3: =Corpus!E3/(Corpus!E3-Corpus!F3) -> 1.4252669 | H3: 0.316 | I3: 0 | J3: 1 | K3: 1 | L3: 1 | M3: =IF(Corpus!Q3="None",1,Corpus!N3/Corpus!H3) -> 1 | N3: =IF(Corpus!Q3="None",1,Corpus!J3/Corpus!H3) -> 1
A4: gpt-5 (non-reasoning) | B4: gpt-5 (minimal) | C4: 57 | D4: 0.8867 | E4: 1.1253 | F4: =Corpus!E4/(Corpus!E4+Corpus!F4) -> 0.82195448 | G4: =Corpus!E4/(Corpus!E4-Corpus!F4) -> 1.2765073 | H4: 0.281 | I4: 0 | J4: 1 | K4: 1 | L4: 1 | M4: =IF(Corpus!Q4="None",1,Corpus!N4/Corpus!H4) -> 1 | N4: =IF(Corpus!Q4="None",1,Corpus!J4/Corpus!H4) -> 1
A5: gpt-5 (low) | B5: gpt-5 (low) | C5: 57 | D5: 0.8833 | E5: 1.1249 | F5: =Corpus!E5/(Corpus!E5+Corpus!F5) -> 0.81291173 | G5: =Corpus!E5/(Corpus!E5-Corpus!F5) -> 1.2989474 | H5: 0.386 | I5: 43 | J5: 2.229 | K5: 0.9725 | L5: 1.0356 | M5: =IF(Corpus!Q5="None",1,Corpus!N5/Corpus!H5) -> 0.51569507 | N5: =IF(Corpus!Q5="None",1,Corpus!J5/Corpus!H5) -> 1.4843049
A6: gpt-5 (medium) | B6: gpt-5 (medium) | C6: 57 | D6: 0.8899 | E6: 1.1299 | F6: =Corpus!E6/(Corpus!E6+Corpus!F6) -> 0.80743692 | G6: =Corpus!E6/(Corpus!E6-Corpus!F6) -> 1.3131749 | H6: 0.281 | I6: 37 | J6: 3.838 | K6: 0.8875 | L6: 1.046 | M6: =IF(Corpus!Q6="None",1,Corpus!N6/Corpus!H6) -> 0.42447917 | N6: =IF(Corpus!Q6="None",1,Corpus!J6/Corpus!H6) -> 1.5130208
A7: gpt-5 (high) | B7: gpt-5 (high) | C7: 56 | D7: 0.8882 | E7: 1.1202 | F7: =Corpus!E7/(Corpus!E7+Corpus!F7) -> 0.81264916 | G7: =Corpus!E7/(Corpus!E7-Corpus!F7) -> 1.2996183 | H7: 0.357 | I7: 32 | J7: 6.116 | K7: 0.951 | L7: 1.0593 | M7: =IF(Corpus!Q7="None",1,Corpus!N7/Corpus!H7) -> 0.52941176 | N7: =IF(Corpus!Q7="None",1,Corpus!J7/Corpus!H7) -> 1.4869281
A8: gpt-5 (xhigh) | B8: gpt-5 (xhigh) | C8: 56 | D8: 0.9 | E8: 1.1394 | F8: =Corpus!E8/(Corpus!E8+Corpus!F8) -> 0.79254658 | G8: =Corpus!E8/(Corpus!E8-Corpus!F8) -> 1.3545648 | H8: 0.321 | I8: 38 | J8: 3.749 | K8: 0.9429 | L8: 1.079 | M8: =IF(Corpus!Q8="None",1,Corpus!N8/Corpus!H8) -> 0.44533333 | N8: =IF(Corpus!Q8="None",1,Corpus!J8/Corpus!H8) -> 1.5386667
A9: gpt-5.2 (non-reasoning) | B9: gpt-5.2 (minimal) | C9: 57 | D9: 0.8907 | E9: 1.1051 | F9: =Corpus!E9/(Corpus!E9+Corpus!F9) -> 0.9030303 | G9: =Corpus!E9/(Corpus!E9-Corpus!F9) -> 1.1203008 | H9: 0.316 | I9: 0 | J9: 1 | K9: 1 | L9: 1 | M9: =IF(Corpus!Q9="None",1,Corpus!N9/Corpus!H9) -> 1 | N9: =IF(Corpus!Q9="None",1,Corpus!J9/Corpus!H9) -> 1
A10: gpt-5.2 (low) | B10: gpt-5.2 (low) | C10: 57 | D10: 0.8991 | E10: 1.1179 | F10: =Corpus!E10/(Corpus!E10+Corpus!F10) -> 0.9047619 | G10: =Corpus!E10/(Corpus!E10-Corpus!F10) -> 1.1176471 | H10: 0.316 | I10: 39 | J10: 1.667 | K10: 0.9779 | L10: 1.0318 | M10: =IF(Corpus!Q10="None",1,Corpus!N10/Corpus!H10) -> 0.61077844 | N10: =IF(Corpus!Q10="None",1,Corpus!J10/Corpus!H10) -> 1.1317365
A11: gpt-5.2 (medium) | B11: gpt-5.2 (medium) | C11: 57 | D11: 0.8998 | E11: 1.1139 | F11: =Corpus!E11/(Corpus!E11+Corpus!F11) -> 0.90186916 | G11: =Corpus!E11/(Corpus!E11-Corpus!F11) -> 1.122093 | H11: 0.298 | I11: 39 | J11: 1.838 | K11: 0.9838 | L11: 1.0163 | M11: =IF(Corpus!Q11="None",1,Corpus!N11/Corpus!H11) -> 0.58152174 | N11: =IF(Corpus!Q11="None",1,Corpus!J11/Corpus!H11) -> 1.2336957
A12: gpt-5.2 (high) | B12: gpt-5.2 (high) | C12: 56 | D12: 0.8995 | E12: 1.101 | F12: =Corpus!E12/(Corpus!E12+Corpus!F12) -> 0.89984351 | G12: =Corpus!E12/(Corpus!E12-Corpus!F12) -> 1.1252446 | H12: 0.339 | I12: 39 | J12: 2.029 | K12: 0.9646 | L12: 1.0078 | M12: =IF(Corpus!Q12="None",1,Corpus!N12/Corpus!H12) -> 0.53694581 | N12: =IF(Corpus!Q12="None",1,Corpus!J12/Corpus!H12) -> 1.1773399
A13: gpt-5.2 (xhigh) | B13: gpt-5.2 (xhigh) | C13: 56 | D13: 0.9016 | E13: 1.1161 | F13: =Corpus!E13/(Corpus!E13+Corpus!F13) -> 0.89545455 | G13: =Corpus!E13/(Corpus!E13-Corpus!F13) -> 1.1321839 | H13: 0.286 | I13: 34 | J13: 3.225 | K13: 0.9268 | L13: 1.0231 | M13: =IF(Corpus!Q13="None",1,Corpus!N13/Corpus!H13) -> 0.45962733 | N13: =IF(Corpus!Q13="None",1,Corpus!J13/Corpus!H13) -> 1.1149068
A14: gpt-5.4-nano (non-reasoning) | B14: gpt-5.4-nano (minimal) | C14: 57 | D14: 0.8914 | E14: 1.114 | F14: =Corpus!E14/(Corpus!E14+Corpus!F14) -> 0.89332573 | G14: =Corpus!E14/(Corpus!E14-Corpus!F14) -> 1.1356055 | H14: 0.281 | I14: 0 | J14: 1 | K14: 1 | L14: 1 | M14: =IF(Corpus!Q14="None",1,Corpus!N14/Corpus!H14) -> 1 | N14: =IF(Corpus!Q14="None",1,Corpus!J14/Corpus!H14) -> 1
... A49: gpt-5.6-terra (xhigh) | B49: gpt-5.6-terra (xhigh) | C49: 40 | D49: 0.8917 | E49: 1.1072 | F49: =Corpus!E49/(Corpus!E49+Corpus!F49) -> 0.9185257 | G49: =Corpus!E49/(Corpus!E49-Corpus!F49) -> 1.0973349 | H49: 0.35 | I49: 39 | J49: 1.684 | K49: 0.9746 | L49: 1.0229 | M49: =IF(Corpus!Q49="None",1,Corpus!N49/Corpus!H49) -> 0.64285714 | N49: =IF(Corpus!Q49="None",1,Corpus!J49/Corpus!H49) -> 1.1547619
A51: Mean fraction of days outside mean±1SD: | H51: =AVERAGE(H3:H49) -> 0.30587234
A52: T and R bands from corpus_summary.py (B = 10,000, seed 20260822). Rows 3-49 cover all 46 measured variants (>= 8 collection days) plus the gpt-5.6-sol (max)* floor row.

Sheet Pinching
A1: Pinching table — Table 11 (Ferson & Ginzburg 1996): envelope top-to-bottom ratio with each factor collapsed to its central in turn. Narrowing = full ratio / pinched ratio. Rows link to Levers.
A2: Model | B2: Full envelope ratio | C2: Pinch A | D2: Pinch PQPC | E2: Pinch P | F2: Pinch T | G2: Pinch R | H2: Narrowing: A | I2: Narrowing: PQPC | J2: Narrowing: P | K2: Narrowing: T | L2: Narrowing: R | N2: Reasoning variant flag (1 = GPT-5.x with measured R; excluded: gpt-4o-mini and rows whose Corpus mode is None) | O2: Pinch A and PQPC together = EXP(total − ln A span − ln PQPC span) | P2: Staged: A + PQPC + T pinched = EXP(total − A − PQPC − T) | Q2: Staged: + R pinched | R2: Staged: + P pinched (= 1 by construction)
A3: =Levers!A3 -> gpt-4o-mini | B3: =Levers!H3 -> 4.0399784 | C3: =EXP(Levers!$G3-Levers!B3) -> 1.4476589 | D3: =EXP(Levers!$G3-Levers!C3) -> 4.0399784 | E3: =EXP(Levers!$G3-Levers!D3) -> 3.7261937 | F3: =EXP(Levers!$G3-Levers!E3) -> 3.0257038 | G3: =EXP(Levers!$G3-Levers!F3) -> 4.0399784 | H3: =B3/C3 -> 2.7906977 | I3: =B3/D3 -> 1 | J3: =B3/E3 -> 1.0842105 | K3: =B3/F3 -> 1.3352194 | L3: =B3/G3 -> 1 | N3: {=IF(AND(A3<>"gpt-4o-mini",INDEX(Corpus!$Q$3:$Q$60,MATCH(A3,Corpus!$A$3:$A$60,0))<>"None"),1,0)} -> 0 | O3: =EXP(Levers!$G3-Levers!$B3-Levers!$C3) -> 1.4476589 | P3: =EXP(Levers!$G3-Levers!$B3-Levers!$C3-Levers!$E3) -> 1.0842105 | Q3: =EXP(Levers!$G3-Levers!$B3-Levers!$C3-Levers!$E3-Levers!$F3) -> 1.0842105 | R3: =EXP(Levers!$G3-Levers!$B3-Levers!$C3-Levers!$E3-Levers!$F3-Levers!$D3) -> 1
A4: =Levers!A4 -> gpt-5 (non-reasoning) | B4: =Levers!H4 -> 10.722693 | C4: =EXP(Levers!$G4-Levers!B4) -> 3.8422983 | D4: =EXP(Levers!$G4-Levers!C4) -> 3.8398833 | E4: =EXP(Levers!$G4-Levers!D4) -> 9.8898623 | F4: =EXP(Levers!$G4-Levers!E4) -> 8.4491351 | G4: =EXP(Levers!$G4-Levers!F4) -> 10.722693 | H4: =B4/C4 -> 2.7906977 | I4: =B4/D4 -> 2.7924528 | J4: =B4/E4 -> 1.0842105 | K4: =B4/F4 -> 1.2690876 | L4: =B4/G4 -> 1 | N4: {=IF(AND(A4<>"gpt-4o-mini",INDEX(Corpus!$Q$3:$Q$60,MATCH(A4,Corpus!$A$3:$A$60,0))<>"None"),1,0)} -> 0 | O4: =EXP(Levers!$G4-Levers!$B4-Levers!$C4) -> 1.3759582 | P4: =EXP(Levers!$G4-Levers!$B4-Levers!$C4-Levers!$E4) -> 1.0842105 | Q4: =EXP(Levers!$G4-Levers!$B4-Levers!$C4-Levers!$E4-Levers!$F4) -> 1.0842105 | R4: =EXP(Levers!$G4-Levers!$B4-Levers!$C4-Levers!$E4-Levers!$F4-Levers!$D4) -> 1
A5: =Levers!A5 -> gpt-5 (low) | B5: =Levers!H5 -> 11.458305 | C5: =EXP(Levers!$G5-Levers!B5) -> 4.1058926 | D5: =EXP(Levers!$G5-Levers!C5) -> 4.1033119 | E5: =EXP(Levers!$G5-Levers!D5) -> 10.568339 | F5: =EXP(Levers!$G5-Levers!E5) -> 8.9973515 | G5: =EXP(Levers!$G5-Levers!F5) -> 10.76014 | H5: =B5/C5 -> 2.7906977 | I5: =B5/D5 -> 2.7924528 | J5: =B5/E5 -> 1.0842105 | K5: =B5/F5 -> 1.2735198 | L5: =B5/G5 -> 1.0648843 | N5: {=IF(AND(A5<>"gpt-4o-mini",INDEX(Corpus!$Q$3:$Q$60,MATCH(A5,Corpus!$A$3:$A$60,0))<>"None"),1,0)} -> 1 | O5: =EXP(Levers!$G5-Levers!$B5-Levers!$C5) -> 1.4703534 | P5: =EXP(Levers!$G5-Levers!$B5-Levers!$C5-Levers!$E5) -> 1.1545588 | Q5: =EXP(Levers!$G5-Levers!$B5-Levers!$C5-Levers!$E5-Levers!$F5) -> 1.0842105 | R5: =EXP(Levers!$G5-Levers!$B5-Levers!$C5-Levers!$E5-Levers!$F5-Levers!$D5) -> 1
A6: =Levers!A6 -> gpt-5 (medium) | B6: =Levers!H6 -> 12.643706 | C6: =EXP(Levers!$G6-Levers!B6) -> 4.5306612 | D6: =EXP(Levers!$G6-Levers!C6) -> 4.5278135 | E6: =EXP(Levers!$G6-Levers!D6) -> 11.66167 | F6: =EXP(Levers!$G6-Levers!E6) -> 9.9580793 | G6: =EXP(Levers!$G6-Levers!F6) -> 10.72781 | H6: =B6/C6 -> 2.7906977 | I6: =B6/D6 -> 2.7924528 | J6: =B6/E6 -> 1.0842105 | K6: =B6/F6 -> 1.2696932 | L6: =B6/G6 -> 1.1785915 | N6: {=IF(AND(A6<>"gpt-4o-mini",INDEX(Corpus!$Q$3:$Q$60,MATCH(A6,Corpus!$A$3:$A$60,0))<>"None"),1,0)} -> 1 | O6: =EXP(Levers!$G6-Levers!$B6-Levers!$C6) -> 1.6224665 | P6: =EXP(Levers!$G6-Levers!$B6-Levers!$C6-Levers!$E6) -> 1.2778414 | Q6: =EXP(Levers!$G6-Levers!$B6-Levers!$C6-Levers!$E6-Levers!$F6) -> 1.0842105 | R6: =EXP(Levers!$G6-Levers!$B6-Levers!$C6-Levers!$E6-Levers!$F6-Levers!$D6) -> 1
A7: =Levers!A7 -> gpt-5 (high) | B7: =Levers!H7 -> 11.869584 | C7: =EXP(Levers!$G7-Levers!B7) -> 4.2532677 | D7: =EXP(Levers!$G7-Levers!C7) -> 4.2505944 | E7: =EXP(Levers!$G7-Levers!D7) -> 10.947675 | F7: =EXP(Levers!$G7-Levers!E7) -> 9.4113237 | G7: =EXP(Levers!$G7-Levers!F7) -> 10.65607 | H7: =B7/C7 -> 2.7906977 | I7: =B7/D7 -> 2.7924528 | J7: =B7/E7 -> 1.0842105 | K7: =B7/F7 -> 1.2612024 | L7: =B7/G7 -> 1.1138801 | N7: {=IF(AND(A7<>"gpt-4o-mini",INDEX(Corpus!$Q$3:$Q$60,MATCH(A7,Corpus!$A$3:$A$60,0))<>"None"),1,0)} -> 1 | O7: =EXP(Levers!$G7-Levers!$B7-Levers!$C7) -> 1.5231297 | P7: =EXP(Levers!$G7-Levers!$B7-Levers!$C7-Levers!$E7) -> 1.2076806 | Q7: =EXP(Levers!$G7-Levers!$B7-Levers!$C7-Levers!$E7-Levers!$F7) -> 1.0842105 | R7: =EXP(Levers!$G7-Levers!$B7-Levers!$C7-Levers!$E7-Levers!$F7-Levers!$D7) -> 1
